<?xml version="1.0" encoding="utf-8"?>
<!-- This URDF was automatically created by SolidWorks to URDF Exporter! Originally created by Stephen Brawner (brawner@gmail.com) 
     Commit Version: 1.5.1-0-g916b5db  Build Version: 1.5.7152.31018
     For more information, please see http://wiki.ros.org/sw_urdf_exporter -->

<!-- Edit by Feng Shihao at 2022/08/03
     I think the inertia tensors generated by sw2URDF are wrong, 
     but I haven't modified it manually -->
<robot  name="OcQ">
    
    <material name="orange">
        <color rgba="1.0 0.423529411765 0.0392156862745 1.0" />
    </material>
    <material name="grey">
        <color rgba="0.439216 0.501961 0.564706 1.0"/>
    </material>

  <link name="trunk">
    <inertial>
      <origin xyz="0.0038891 -1.8528E-17 -0.0038942" rpy="0 0 0" />
      <mass value="5.527" />
      <inertia
        ixx="0.0091308"
        ixy="-4.6535E-06"
        ixz="-3.9302E-19"
        iyy="0.010512"
        iyz="1.7978E-18"
        izz="0.013683" />
    </inertial>
    <visual>
      <origin xyz="0 0 0" rpy="0 0 0" />
      <geometry>
        <mesh filename="package://OcQ/meshes/trunk.STL" />
      </geometry>
      <material name="grey"/>
    </visual>
    <collision>
      <origin xyz="0 0 0" rpy="0 0 0" />
      <geometry>
        <mesh filename="package://OcQ/meshes/trunk.STL" />
      </geometry>
    </collision>
  </link>

<!-- =============================== -->
<!-- 腿FR -->
  <link name="link_FR1">
    <inertial>
      <origin xyz="-0.0026008 0.015277 -4.2121E-05" rpy="0 0 0" />
      <mass value="0.76385" />
      <inertia
        ixx="0.00052579"
        ixy="-1.4101E-06"
        ixz="9.3834E-07"
        iyy="0.00095509"
        iyz="7.6751E-07"
        izz="0.00060585" />
    </inertial>
    <visual>
      <origin xyz="0 0 0" rpy="0 0 0" />
      <geometry>
        <mesh filename="package://OcQ/meshes/link_FR1.STL" />
      </geometry>
      <material name="grey"/>
    </visual>
    <collision>
      <origin xyz="0 0 0" rpy="0 0 0" />
      <geometry>
        <mesh filename="package://OcQ/meshes/link_FR1.STL" />
      </geometry>
    </collision>
  </link>
  <joint name="joint_FR1" type="revolute">
    <origin xyz="0.2155 -0.0625 0" rpy="0 0 0" />
    <parent link="trunk" />
    <child link="link_FR1" />
    <axis xyz="1 0 0" />
    <limit
      lower="-1.83"
      upper="0."
      effort="33.5"
      velocity="21" />
  </joint>
<!-- =============================== -->
  <link name="link_FR21">
    <inertial>
      <origin xyz="0.011662 0.0021403 -0.079655" rpy="0 0 0" />
      <mass value="0.092904" />
      <inertia
        ixx="4.3299E-05"
        ixy="5.3853E-08"
        ixz="7.0254E-06"
        iyy="5.1116E-05"
        iyz="3.1577E-07"
        izz="1.3903E-05" />
    </inertial>
    <visual>
      <origin xyz="0 0 0" rpy="0 0 0" />
      <geometry>
        <mesh filename="package://OcQ/meshes/link_FR21.STL" />
      </geometry>
      <material name="grey"/>
    </visual>
    <collision>
      <origin xyz="0 0 0" rpy="0 0 0" />
      <geometry>
        <mesh filename="package://OcQ/meshes/link_FR21.STL" />
      </geometry>
    </collision>
  </link>
  <joint name="joint_FR21" type="revolute">
    <origin xyz="0 -0.0689 0" rpy="0 0 0" />
    <parent link="link_FR1" />
    <child link="link_FR21" />
    <axis xyz="0 1 0" />
    <limit
      lower="-1.575"
      upper="1.575"
      effort="33.5"
      velocity="21" />
  </joint>
<!-- =============================== -->
  <link name="link_FR22">
    <inertial>
      <origin xyz="0.0065546 0.011426 -0.079849" rpy="0 0 0" />
      <mass value="0.049725" />
      <inertia
        ixx="3.5507E-05"
        ixy="-1.9526E-08"
        ixz="1.2433E-07"
        iyy="3.5725E-05"
        iyz="1.815E-09"
        izz="5.8841E-06" />
    </inertial>
    <visual>
      <origin xyz="0 0 0" rpy="0 0 0" />
      <geometry>
        <mesh filename="package://OcQ/meshes/link_FR22.STL" />
      </geometry>
      <material name="grey"/>
    </visual>
    <collision>
      <origin
        xyz="0 0 0"
        rpy="0 0 0" />
      <geometry>
        <mesh filename="package://OcQ/meshes/link_FR22.STL" />
      </geometry>
    </collision>
  </link>
  <joint name="joint_FR22" type="revolute">
    <origin xyz="0 0 -0.16" rpy="0 0 -1.0472" />
    <parent link="link_FR21" />
    <child link="link_FR22" />
    <axis xyz="0 1 0" />
    <limit
      lower="0.3464"
      upper="2.2143"
      effort="100"
      velocity="100" />
  </joint>
<!-- =============================== -->
  <link name="link_FR31">
    <inertial>
      <origin xyz="-0.00088016 0.030832 -0.0056839" rpy="0 0 0" />
      <mass  value="0.77501" />
      <inertia
        ixx="0.00049676"
        ixy="-6.0125E-08"
        ixz="-6.7119E-06"
        iyy="0.00078679"
        iyz="-5.0166E-06"
        izz="0.00046366" />
    </inertial>
    <visual>
      <origin xyz="0 0 0" rpy="0 0 0" />
      <geometry>
        <mesh filename="package://OcQ/meshes/link_FR31.STL" />
      </geometry>
      <material name="grey"/>
    </visual>
    <collision>
      <origin xyz="0 0 0" rpy="0 0 0" />
      <geometry>
        <mesh filename="package://OcQ/meshes/link_FR31.STL" />
      </geometry>
    </collision>
  </link>
  <joint name="joint_FR31" type="revolute">
    <origin xyz="0 -0.0689 0" rpy="0 0 0" />
    <parent  link="link_FR1" />
    <child link="link_FR31" />
    <axis xyz="0 1 0" />
    <limit
      lower="-1.575"
      upper="1.575"
      effort="33.5"
      velocity="21" />
  </joint>
<!-- =============================== -->
  <link name="link_FR32">
    <inertial>
      <origin  xyz="0.0037103 -0.010522 -0.088706"  rpy="0 0 0" />
      <mass value="0.092646" />
      <inertia
        ixx="6.3696E-05"
        ixy="-8.9378E-07"
        ixz="1.6953E-07"
        iyy="6.4698E-05"
        iyz="7.0781E-07"
        izz="1.0355E-05" />
    </inertial>
    <visual>
      <origin xyz="0 0 0" rpy="0 0 0" />
      <geometry>
        <mesh filename="package://OcQ/meshes/link_FR32.STL" />
      </geometry>
      <material name="grey"/>
    </visual>
    <collision>
      <origin  xyz="0 0 0" rpy="0 0 0" />
      <geometry>
        <mesh filename="package://OcQ/meshes/link_FR32.STL" />
      </geometry>
    </collision>
  </link>
  <joint name="joint_FR32" type="revolute">
    <origin xyz="0 0 -0.16" rpy="0 0 -2.0944" />
    <parent  link="link_FR31" />
    <child link="link_FR32" />
    <axis xyz="0 1 0" />
    <limit
      lower="0.3464"
      upper="2.2143"
      effort="100"
      velocity="100" />
  </joint>
<!-- =============================== -->
<!-- 添加足端，方便碰撞检测 -->
  <link name="foot_FR">
    <inertial>
      <origin xyz="0 0 0" rpy="0 0 0" />
      <mass value="0.009" />
      <inertia ixx="1e-06" ixy="0.0" ixz="0.0" iyy="1e-06" iyz="0.0" izz="1e-06" />
    </inertial>
    <visual>
      <origin xyz="0.015 0 0" rpy="0 0 0" />
      <geometry>
        <sphere radius="0.012"/>
      </geometry>
      <material name="orange"/>
    </visual>
    <collision>
      <origin xyz="0 0 0" rpy="0 0 0" />
      <geometry>
        <sphere radius="0.012"/>
      </geometry>
    </collision>
  </link>
  <joint name="joint_foot_FR" type="fixed">
    <origin xyz="0 0 -0.183" rpy="0 0 -1.0472" />
    <parent link="link_FR32" />
    <child link="foot_FR" />
  </joint>

<!-- =============================== -->
<!-- 腿FL -->
  <link  name="link_FL1">
    <inertial>
      <origin  xyz="-0.0026008 -0.015277 4.2121E-05" rpy="0 0 0" />
      <mass value="0.76385" />
      <inertia
        ixx="0.00052579"
        ixy="1.4101E-06"
        ixz="-9.3834E-07"
        iyy="0.00095509"
        iyz="7.6751E-07"
        izz="0.00060585" />
    </inertial>
    <visual>
      <origin xyz="0 0 0" rpy="0 0 0" />
      <geometry>
        <mesh filename="package://OcQ/meshes/link_FL1.STL" />
      </geometry>
      <material name="grey"/>
    </visual>
    <collision>
      <origin xyz="0 0 0" rpy="0 0 0" />
      <geometry>
        <mesh  filename="package://OcQ/meshes/link_FL1.STL" />
      </geometry>
    </collision>
  </link>
  <joint name="joint_FL1" type="revolute">
    <origin xyz="0.2155 0.0625 0" rpy="0 0 0" />
    <parent link="trunk" />
    <child link="link_FL1" />
    <axis  xyz="1 0 0" />
    <limit
      lower="0."
      upper="1.83"
      effort="33.5"
      velocity="21" />
  </joint>
<!-- =============================== -->
  <link name="link_FL21">
    <inertial>
      <origin xyz="0.00089316 -0.03075 -0.0058206" rpy="0 0 0" />
      <mass value="0.77706" />
      <inertia
        ixx="0.00049697"
        ixy="-6.0128E-08"
        ixz="6.7117E-06"
        iyy="0.00078687"
        iyz="5.0166E-06"
        izz="0.00046394" />
    </inertial>
    <visual>
      <origin xyz="0 0 0" rpy="0 0 0" />
      <geometry>
        <mesh filename="package://OcQ/meshes/link_FL21.STL" />
      </geometry>
      <material name="grey"/>
    </visual>
    <collision>
      <origin xyz="0 0 0" rpy="0 0 0" />
      <geometry>
        <mesh filename="package://OcQ/meshes/link_FL21.STL" />
      </geometry>
    </collision>
  </link>
  <joint name="joint_FL21" type="revolute">
    <origin xyz="0 0.0689 0" rpy="0 0 0" />
    <parent link="link_FL1" />
    <child link="link_FL21" />
    <axis xyz="0 1 0" />
    <limit
      lower="-1.575"
      upper="1.575"
      effort="33.5"
      velocity="21" />
  </joint>
<!-- =============================== -->
  <link name="link_FL22">
    <inertial>
      <origin xyz="-0.0049407 0.014279 -0.059817" rpy="0 0 0" />
      <mass  value="0.066317" />
      <inertia
        ixx="3.6592E-05"
        ixy="-1.2374E-07"
        ixz="-2.5622E-07"
        iyy="3.6705E-05"
        iyz="-5.5762E-07"
        izz="6.7216E-06" />
    </inertial>
    <visual>
      <origin  xyz="0 0 0" rpy="0 0 0" />
      <geometry>
        <mesh  filename="package://OcQ/meshes/link_FL22.STL" />
      </geometry>
      <material name="grey"/>
    </visual>
    <collision>
      <origin  xyz="0 0 0"  rpy="0 0 0" />
      <geometry>
        <mesh filename="package://OcQ/meshes/link_FL22.STL" />
      </geometry>
    </collision>
  </link>
  <joint name="joint_FL22" type="revolute">
    <origin xyz="0 0 -0.16" rpy="0 0 -2.0944" />
    <parent link="link_FL21" />
    <child link="link_FL22" />
    <axis  xyz="0 1 0" />
    <limit
      lower="-2.2143"
      upper="-0.3464"
      effort="100"
      velocity="100" />
  </joint>
<!-- =============================== -->
  <link name="link_FL31">
    <inertial>
      <origin xyz="-0.011662 -0.0021403 -0.079655" rpy="0 0 0" />
      <mass value="0.092904" />
      <inertia
        ixx="4.3299E-05"
        ixy="5.3853E-08"
        ixz="-7.0254E-06"
        iyy="5.1116E-05"
        iyz="-3.1577E-07"
        izz="1.3903E-05" />
    </inertial>
    <visual>
      <origin xyz="0 0 0" rpy="0 0 0" />
      <geometry>
        <mesh  filename="package://OcQ/meshes/link_FL31.STL" />
      </geometry>
      <material name="grey"/>
    </visual>
    <collision>
      <origin xyz="0 0 0" rpy="0 0 0" />
      <geometry>
        <mesh filename="package://OcQ/meshes/link_FL31.STL" />
      </geometry>
    </collision>
  </link>
  <joint name="joint_FL31" type="revolute">
    <origin xyz="0 0.0689 0"  rpy="0 0 0" />
    <parent link="link_FL1" />
    <child link="link_FL31" />
    <axis  xyz="0 1 0" />
    <limit
      lower="-1.575"
      upper="1.575"
      effort="33.5"
      velocity="21" />
  </joint>
<!-- =============================== -->
  <link name="link_FL32">
    <inertial>
      <origin xyz="-0.004497 -0.007837 -0.10811" rpy="0 0 0" />
      <mass  value="0.076054" />
      <inertia
        ixx="6.2607E-05"
        ixy="7.5051E-07"
        ixz="-3.7639E-08"
        iyy="6.3714E-05"
        iyz="1.4838E-07"
        izz="9.5171E-06" />
    </inertial>
    <visual>
      <origin xyz="0 0 0" rpy="0 0 0" />
      <geometry>
        <mesh filename="package://OcQ/meshes/link_FL32.STL" />
      </geometry>
      <material name="grey"/>
    </visual>
    <collision>
      <origin xyz="0 0 0" rpy="0 0 0" />
      <geometry>
        <mesh filename="package://OcQ/meshes/link_FL32.STL" />
      </geometry>
    </collision>
  </link>
  <joint  name="joint_FL32" type="revolute">
    <origin xyz="0 0 -0.16" rpy="0 0 -1.0472" />
    <parent link="link_FL31" />
    <child link="link_FL32" />
    <axis xyz="0 1 0" />
    <limit
      lower="-2.2143"
      upper="-0.3464"
      effort="100"
      velocity="100" />
  </joint>
<!-- =============================== -->
<!-- 人为添加足端，方便碰撞检测 -->
  <link name="foot_FL">
    <inertial>
      <origin xyz="0 0 0" rpy="0 0 0" />
      <mass value="0.009" />
      <inertia ixx="1e-06" ixy="0.0" ixz="0.0" iyy="1e-06" iyz="0.0" izz="1e-06" />
    </inertial>
    <visual>
      <origin xyz="0.015 0 0" rpy="0 0 0" />
      <geometry>
        <sphere radius="0.012"/>
      </geometry>
      <material name="orange"/>
    </visual>
    <collision>
      <origin xyz="0 0 0" rpy="0 0 0" />
      <geometry>
        <sphere radius="0.012"/>
      </geometry>
    </collision>
  </link>
  <joint name="joint_foot_FL" type="fixed">
    <origin xyz="0 0 -0.183" rpy="0 0 -2.0944" />
    <parent link="link_FL32" />
    <child link="foot_FL" />
  </joint>

<!-- =============================== -->
<!-- 腿RR -->
  <link name="link_RR1">
    <inertial>
      <origin  xyz="0.0026008 0.015277 4.2121E-05" rpy="0 0 0" />
      <mass  value="0.76385" />
      <inertia
        ixx="0.00052579"
        ixy="1.4101E-06"
        ixz="9.3834E-07"
        iyy="0.00095509"
        iyz="-7.6751E-07"
        izz="0.00060585" />
    </inertial>
    <visual>
      <origin  xyz="0 0 0" rpy="0 0 0" />
      <geometry>
        <mesh filename="package://OcQ/meshes/link_RR1.STL" />
      </geometry>
      <material name="grey"/>
    </visual>
    <collision>
      <origin xyz="0 0 0"  rpy="0 0 0" />
      <geometry>
        <mesh filename="package://OcQ/meshes/link_RR1.STL" />
      </geometry>
    </collision>
  </link>
  <joint name="joint_RR1" type="revolute">
    <origin xyz="-0.2155 -0.0625 0" rpy="0 0 0" />
    <parent link="trunk" />
    <child link="link_RR1" />
    <axis xyz="1 0 0" />
    <limit
      lower="-1.83"
      upper="0."
      effort="33.5"
      velocity="21" />
  </joint>
<!-- =============================== -->
  <link name="link_RR21">
    <inertial>
      <origin xyz="0.011662 0.0021403 -0.079655" rpy="0 0 0" />
      <mass value="0.092904" />
      <inertia
        ixx="4.3299E-05"
        ixy="5.3853E-08"
        ixz="7.0254E-06"
        iyy="5.1116E-05"
        iyz="3.1577E-07"
        izz="1.3903E-05" />
    </inertial>
    <visual>
      <origin xyz="0 0 0" rpy="0 0 0" />
      <geometry>
        <mesh filename="package://OcQ/meshes/link_RR21.STL" />
      </geometry>
      <material name="grey"/>
    </visual>
    <collision>
      <origin xyz="0 0 0" rpy="0 0 0" />
      <geometry>
        <mesh filename="package://OcQ/meshes/link_RR21.STL" />
      </geometry>
    </collision>
  </link>
  <joint name="joint_RR21"  type="revolute">
    <origin xyz="0 -0.0689 0" rpy="0 0 0" />
    <parent link="link_RR1" />
    <child link="link_RR21" />
    <axis xyz="0 1 0" />
    <limit
      lower="-1.575"
      upper="1.575"
      effort="33.5"
      velocity="21" />
  </joint> 
<!-- =============================== -->
  <link name="link_RR22">
    <inertial>
      <origin xyz="0.004497 0.007837 -0.10811" rpy="0 0 0" />
      <mass  value="0.076054" />
      <inertia
        ixx="6.2607E-05"
        ixy="7.5051E-07"
        ixz="3.7639E-08"
        iyy="6.3714E-05"
        iyz="-1.4838E-07"
        izz="9.5171E-06" />
    </inertial>
    <visual>
      <origin xyz="0 0 0" rpy="0 0 0" />
      <geometry>
        <mesh filename="package://OcQ/meshes/link_RR22.STL" />
      </geometry>
      <material name="grey"/>
    </visual>
    <collision>
      <origin  xyz="0 0 0" rpy="0 0 0" />
      <geometry>
        <mesh filename="package://OcQ/meshes/link_RR22.STL" />
      </geometry>
    </collision>
  </link>
  <joint name="joint_RR22" type="revolute">
    <origin xyz="0 0 -0.16" rpy="0 0 -1.0472" />
    <parent link="link_RR21" />
    <child link="link_RR22" />
    <axis xyz="0 1 0" />
    <limit
      lower="0.3464"
      upper="2.2143"
      effort="100"
      velocity="100" />
  </joint>
<!-- =============================== -->
  <link name="link_RR31">
    <inertial>
      <origin xyz="-0.00089316 0.03075 -0.0058206" rpy="0 0 0" />
      <mass value="0.77706" />
      <inertia
        ixx="0.00049697"
        ixy="-6.0128E-08"
        ixz="-6.7117E-06"
        iyy="0.00078687"
        iyz="-5.0166E-06"
        izz="0.00046394" />
    </inertial>
    <visual>
      <origin xyz="0 0 0" rpy="0 0 0" />
      <geometry>
        <mesh filename="package://OcQ/meshes/link_RR31.STL" />
      </geometry>
      <material name="grey"/>
    </visual>
    <collision>
      <origin xyz="0 0 0" rpy="0 0 0" />
      <geometry>
        <mesh filename="package://OcQ/meshes/link_RR31.STL" />
      </geometry>
    </collision>
  </link>
  <joint name="joint_RR31" type="revolute">
    <origin xyz="0 -0.0689 0"  rpy="0 0 0" />
    <parent link="link_RR1" />
    <child  link="link_RR31" />
    <axis xyz="0 1 0" />
    <limit
      lower="-1.575"
      upper="1.575"
      effort="33.5"
      velocity="21" />
  </joint>
<!-- =============================== -->
  <link name="link_RR32">
    <inertial>
      <origin  xyz="0.0049407 -0.014279 -0.059817"  rpy="0 0 0" />
      <mass value="0.066317" />
      <inertia
        ixx="3.6599E-05"
        ixy="-1.2374E-07"
        ixz="2.5622E-07"
        iyy="3.6712E-05"
        iyz="5.5762E-07"
        izz="6.7216E-06" />
    </inertial>
    <visual>
      <origin xyz="0 0 0" rpy="0 0 0" />
      <geometry>
        <mesh filename="package://OcQ/meshes/link_RR32.STL" />
      </geometry>
      <material name="grey"/>
    </visual>
    <collision>
      <origin xyz="0 0 0" rpy="0 0 0" />
      <geometry>
        <mesh  filename="package://OcQ/meshes/link_RR32.STL" />
      </geometry>
    </collision>
  </link>
  <joint name="joint_RR32" type="revolute">
    <origin xyz="0 0 -0.16" rpy="0 0 -2.0944" />
    <parent link="link_RR31" />
    <child link="link_RR32" />
    <axis xyz="0 1 0" />
    <limit
      lower="0.3464"
      upper="2.2143"
      effort="100"
      velocity="100" />
  </joint>
<!-- =============================== -->
<!-- 人为添加足端，方便碰撞检测 -->
  <link name="foot_RR">
    <inertial>  <origin xyz="0 0 0" rpy="0 0 0" />
      <mass value="0.009" />
      <inertia ixx="1e-06" ixy="0.0" ixz="0.0" iyy="1e-06" iyz="0.0" izz="1e-06" />
    </inertial>
    <visual>
      <origin xyz="-0.015 0 0" rpy="0 0 0" />
      <geometry>
        <sphere radius="0.012"/>
      </geometry>
      <material name="orange"/>
    </visual>
    <collision>
      <origin xyz="0 0 0" rpy="0 0 0" />
      <geometry>
        <sphere radius="0.012"/>
      </geometry>
    </collision>
  </link>
  <joint name="joint_foot_RR" type="fixed">
    <origin xyz="0 0 -0.183" rpy="0 0 -2.0944" />
    <parent link="link_RR22" />
    <child link="foot_RR" />
  </joint>

<!-- =============================== -->
<!-- 腿RL -->
  <link name="link_RL1">
    <inertial>
      <origin xyz="0.0026008 -0.015277 -4.2121E-05" rpy="0 0 0" />
      <mass value="0.76385" />
      <inertia
        ixx="0.00052579"
        ixy="-1.4101E-06"
        ixz="-9.3834E-07"
        iyy="0.00095509"
        iyz="-7.6751E-07"
        izz="0.00060585" />
    </inertial>
    <visual>
      <origin xyz="0 0 0" rpy="0 0 0" />
      <geometry>
        <mesh filename="package://OcQ/meshes/link_RL1.STL" />
      </geometry>
      <material name="grey"/>
    </visual>
    <collision>
      <origin xyz="0 0 0"  rpy="0 0 0" />
      <geometry>
        <mesh  filename="package://OcQ/meshes/link_RL1.STL" />
      </geometry>
    </collision>
  </link>
  <joint name="joint_RL1" type="revolute">
    <origin xyz="-0.2155 0.0625 0"  rpy="0 0 0" />
    <parent link="trunk" />
    <child link="link_RL1" />
    <axis  xyz="1 0 0" />
    <limit
      lower="0."
      upper="1.83"
      effort="33.5"
      velocity="21" />
  </joint>
<!-- =============================== -->
  <link name="link_RL21">
    <inertial>
      <origin xyz="0.00089316 -0.03075 -0.0058206" rpy="0 0 0" />
      <mass value="0.77706" />
      <inertia
        ixx="0.00049697"
        ixy="-6.0128E-08"
        ixz="6.7117E-06"
        iyy="0.00078687"
        iyz="5.0166E-06"
        izz="0.00046394" />
    </inertial>
    <visual>
      <origin  xyz="0 0 0"  rpy="0 0 0" />
      <geometry>
        <mesh filename="package://OcQ/meshes/link_RL21.STL" />
      </geometry>
      <material name="grey"/>
    </visual>
    <collision>
      <origin xyz="0 0 0"  rpy="0 0 0" />
      <geometry>
        <mesh filename="package://OcQ/meshes/link_RL21.STL" />
      </geometry>
    </collision>
  </link>
  <joint  name="joint_RL21" type="revolute">
    <origin xyz="0 0.0689 0" rpy="0 0 0" />
    <parent  link="link_RL1" />
    <child  link="link_RL21" />
    <axis  xyz="0 1 0" />
    <limit
      lower="-1.575"
      upper="1.575"
      effort="33.5"
      velocity="21" />
  </joint>
<!-- =============================== -->
  <link name="link_RL22">
    <inertial>
      <origin xyz="-0.0037103 0.010522 -0.088706" rpy="0 0 0" />
      <mass  value="0.092646" />
      <inertia
        ixx="6.3696E-05"
        ixy="-8.9378E-07"
        ixz="-1.6953E-07"
        iyy="6.4698E-05"
        iyz="-7.0781E-07"
        izz="1.0355E-05" />
    </inertial>
    <visual>
      <origin xyz="0 0 0" rpy="0 0 0" />
      <geometry>
        <mesh  filename="package://OcQ/meshes/link_RL22.STL" />
      </geometry>
      <material name="grey"/>
    </visual>
    <collision>
      <origin xyz="0 0 0" rpy="0 0 0" />
      <geometry>
        <mesh  filename="package://OcQ/meshes/link_RL22.STL" />
      </geometry>
    </collision>
  </link>
  <joint name="joint_RL22"  type="revolute">
    <origin xyz="0 0 -0.16"  rpy="0 0 -2.0944" />
    <parent  link="link_RL21" />
    <child link="link_RL22" />
    <axis  xyz="0 1 0" />
    <limit
      lower="-2.2143"
      upper="-0.3464"
      effort="100"
      velocity="100" />
  </joint>
<!-- =============================== -->
  <link
    name="link_RL31">
    <inertial>
      <origin  xyz="-0.011662 -0.0021403 -0.079655" rpy="0 0 0" />
      <mass value="0.092904" />
      <inertia
        ixx="4.3299E-05"
        ixy="5.3853E-08"
        ixz="-7.0254E-06"
        iyy="5.1116E-05"
        iyz="-3.1577E-07"
        izz="1.3903E-05" />
    </inertial>
    <visual>
      <origin xyz="0 0 0" rpy="0 0 0" />
      <geometry>
        <mesh filename="package://OcQ/meshes/link_RL31.STL" />
      </geometry>
      <material name="grey"/>
    </visual>
    <collision>
      <origin  xyz="0 0 0" rpy="0 0 0" />
      <geometry>
        <mesh  filename="package://OcQ/meshes/link_RL31.STL" />
      </geometry>
    </collision>
  </link>
  <joint  name="joint_RL31" type="revolute">
    <origin  xyz="0 0.0689 0"  rpy="0 0 0" />
    <parent link="link_RL1" />
    <child link="link_RL31" />
    <axis  xyz="0 1 0" />
    <limit
      lower="-1.575"
      upper="1.575"
      effort="33.5"
      velocity="21" />
  </joint>
<!-- =============================== -->
  <link name="link_RL32">
    <inertial>
      <origin  xyz="-0.0065546 -0.011426 -0.079849" rpy="0 0 0" />
      <mass value="0.049725" />
      <inertia
        ixx="3.5507E-05"
        ixy="-1.9526E-08"
        ixz="-1.2433E-07"
        iyy="3.5725E-05"
        iyz="-1.815E-09"
        izz="5.8841E-06" />
    </inertial>
    <visual>
      <origin  xyz="0 0 0" rpy="0 0 0" />
      <geometry>
        <mesh filename="package://OcQ/meshes/link_RL32.STL" />
      </geometry>
      <material name="grey"/>
    </visual>
    <collision>
      <origin  xyz="0 0 0"  rpy="0 0 0" />
      <geometry>
        <mesh filename="package://OcQ/meshes/link_RL32.STL" />
      </geometry>
    </collision>
  </link>
  <joint name="joint_RL32" type="revolute">
    <origin xyz="0 0 -0.16" rpy="0 0 -1.0472" />
    <parent link="link_RL31" />
    <child link="link_RL32" />
    <axis xyz="0 1 0" />
    <limit
      lower="-2.2143"
      upper="-0.3464"
      effort="100"
      velocity="100" />
  </joint>
<!-- =============================== -->
<!-- 人为添加足端，方便碰撞检测 -->
  <link name="foot_RL">
    <inertial>
      <origin xyz="0 0 0" rpy="0 0 0" />
      <mass value="0.009" />
      <inertia ixx="1e-06" ixy="0.0" ixz="0.0" iyy="1e-06" iyz="0.0" izz="1e-06" />
    </inertial>
    <visual>
      <origin xyz="-0.015 0 0" rpy="0 0 0" />
      <geometry>
        <sphere radius="0.012"/>
      </geometry>
      <material name="orange"/>
    </visual>
    <collision>
      <origin xyz="0 0 0" rpy="0 0 0" />
      <geometry>
        <sphere radius="0.012"/>
      </geometry>
    </collision>
  </link>
  <joint name="joint_foot_RL" type="fixed">
    <origin xyz="0 0 -0.183" rpy="0 0 -1.0472" />
    <parent link="link_RL22" />
    <child link="foot_RL" />
  </joint>
</robot>